/usr/lib/python3/dist-packages/requests/__init__.py:89: RequestsDependencyWarning: urllib3 (1.26.8) or chardet (3.0.4) doesn't match a supported version!
  warnings.warn("urllib3 ({}) or chardet ({}) doesn't match a supported "
Traceback (most recent call last):
  File "main.py", line 9, in <module>
    from config import config
  File "/root/telegram/config/config.py", line 7, in <module>
    config_data = json.load(file)
  File "/usr/lib/python3.8/json/__init__.py", line 293, in load
    return loads(fp.read(),
  File "/usr/lib/python3.8/json/__init__.py", line 357, in loads
    return _default_decoder.decode(s)
  File "/usr/lib/python3.8/json/decoder.py", line 337, in decode
    obj, end = self.raw_decode(s, idx=_w(s, 0).end())
  File "/usr/lib/python3.8/json/decoder.py", line 353, in raw_decode
    obj, end = self.scan_once(s, idx)
json.decoder.JSONDecodeError: Expecting property name enclosed in double quotes: line 16 column 3 (char 1352)
/usr/lib/python3/dist-packages/requests/__init__.py:89: RequestsDependencyWarning: urllib3 (1.26.8) or chardet (3.0.4) doesn't match a supported version!
  warnings.warn("urllib3 ({}) or chardet ({}) doesn't match a supported "
Traceback (most recent call last):
  File "main.py", line 9, in <module>
    from config import config
  File "/root/telegram/config/config.py", line 7, in <module>
    config_data = json.load(file)
  File "/usr/lib/python3.8/json/__init__.py", line 293, in load
    return loads(fp.read(),
  File "/usr/lib/python3.8/json/__init__.py", line 357, in loads
    return _default_decoder.decode(s)
  File "/usr/lib/python3.8/json/decoder.py", line 337, in decode
    obj, end = self.raw_decode(s, idx=_w(s, 0).end())
  File "/usr/lib/python3.8/json/decoder.py", line 353, in raw_decode
    obj, end = self.scan_once(s, idx)
json.decoder.JSONDecodeError: Expecting property name enclosed in double quotes: line 16 column 3 (char 1352)
python3: can't open file 'reset.py': [Errno 2] No such file or directory
2022-10-17 12:15:28,644 - DISCORD - INFO - Logged in as CP Signals#3844
/usr/lib/python3/dist-packages/requests/__init__.py:89: RequestsDependencyWarning: urllib3 (1.26.12) or chardet (5.0.0) doesn't match a supported version!
  warnings.warn("urllib3 ({}) or chardet ({}) doesn't match a supported "
Traceback (most recent call last):
  File "main.py", line 127, in <module>
    with telegram_client as tc:
  File "/usr/local/lib/python3.8/dist-packages/telethon/helpers.py", line 219, in _sync_enter
    return loop.run_until_complete(self.__aenter__())
  File "/usr/lib/python3.8/asyncio/base_events.py", line 616, in run_until_complete
    return future.result()
  File "/usr/local/lib/python3.8/dist-packages/telethon/client/auth.py", line 735, in __aenter__
    return await self.start()
  File "/usr/local/lib/python3.8/dist-packages/telethon/client/auth.py", line 141, in _start
    await self.connect()
  File "/usr/local/lib/python3.8/dist-packages/telethon/client/telegrambaseclient.py", line 537, in connect
    self.session.auth_key = self._sender.auth_key
  File "/usr/local/lib/python3.8/dist-packages/telethon/sessions/sqlite.py", line 180, in auth_key
    self._update_session_table()
  File "/usr/local/lib/python3.8/dist-packages/telethon/sessions/sqlite.py", line 194, in _update_session_table
    c.execute('delete from sessions')
sqlite3.OperationalError: database is locked
Task was destroyed but it is pending!
task: <Task pending name='Task-3' coro=<Connection._send_loop() running at /usr/local/lib/python3.8/dist-packages/telethon/network/connection/connection.py:311> wait_for=<Future pending cb=[<TaskWakeupMethWrapper object at 0x7f6e4293da60>()]>>
Task was destroyed but it is pending!
task: <Task pending name='Task-4' coro=<Connection._recv_loop() running at /usr/local/lib/python3.8/dist-packages/telethon/network/connection/connection.py:329> wait_for=<Future pending cb=[<TaskWakeupMethWrapper object at 0x7f6e4293db50>()]>>
Task was destroyed but it is pending!
task: <Task pending name='Task-5' coro=<MTProtoSender._send_loop() running at /usr/local/lib/python3.8/dist-packages/telethon/network/mtprotosender.py:458> wait_for=<Future pending cb=[<TaskWakeupMethWrapper object at 0x7f6e4293dcd0>()]>>
Task was destroyed but it is pending!
task: <Task pending name='Task-6' coro=<MTProtoSender._recv_loop() running at /usr/local/lib/python3.8/dist-packages/telethon/network/mtprotosender.py:501> wait_for=<Future pending cb=[<TaskWakeupMethWrapper object at 0x7f6e4293dd00>()]>>
2022-10-17 12:16:02,998 - TELEGRAM - INFO - Message received from -1001715864961
2022-10-17 12:16:04,042 - TELEGRAM - INFO - A message was forwarded from -1001715864961 to logs(869952469516570694)
Please enter your phone (or bot token): /usr/lib/python3/dist-packages/requests/__init__.py:89: RequestsDependencyWarning: urllib3 (1.26.12) or chardet (5.0.0) doesn't match a supported version!
  warnings.warn("urllib3 ({}) or chardet ({}) doesn't match a supported "
Traceback (most recent call last):
  File "main.py", line 127, in <module>
    with telegram_client as tc:
  File "/usr/local/lib/python3.8/dist-packages/telethon/helpers.py", line 219, in _sync_enter
    return loop.run_until_complete(self.__aenter__())
  File "/usr/lib/python3.8/asyncio/base_events.py", line 616, in run_until_complete
    return future.result()
  File "/usr/local/lib/python3.8/dist-packages/telethon/client/auth.py", line 735, in __aenter__
    return await self.start()
  File "/usr/local/lib/python3.8/dist-packages/telethon/client/auth.py", line 171, in _start
    value = phone()
  File "/usr/local/lib/python3.8/dist-packages/telethon/client/auth.py", line 22, in <lambda>
    phone: typing.Callable[[], str] = lambda: input('Please enter your phone (or bot token): '),
OSError: [Errno 9] Bad file descriptor
Please enter your phone (or bot token): /usr/lib/python3/dist-packages/requests/__init__.py:89: RequestsDependencyWarning: urllib3 (1.26.12) or chardet (5.0.0) doesn't match a supported version!
  warnings.warn("urllib3 ({}) or chardet ({}) doesn't match a supported "
Traceback (most recent call last):
  File "main.py", line 127, in <module>
    with telegram_client as tc:
  File "/usr/local/lib/python3.8/dist-packages/telethon/helpers.py", line 219, in _sync_enter
    return loop.run_until_complete(self.__aenter__())
  File "/usr/lib/python3.8/asyncio/base_events.py", line 616, in run_until_complete
    return future.result()
  File "/usr/local/lib/python3.8/dist-packages/telethon/client/auth.py", line 735, in __aenter__
    return await self.start()
  File "/usr/local/lib/python3.8/dist-packages/telethon/client/auth.py", line 171, in _start
    value = phone()
  File "/usr/local/lib/python3.8/dist-packages/telethon/client/auth.py", line 22, in <lambda>
    phone: typing.Callable[[], str] = lambda: input('Please enter your phone (or bot token): '),
OSError: [Errno 9] Bad file descriptor
Please enter your phone (or bot token): /usr/lib/python3/dist-packages/requests/__init__.py:89: RequestsDependencyWarning: urllib3 (1.26.12) or chardet (5.0.0) doesn't match a supported version!
  warnings.warn("urllib3 ({}) or chardet ({}) doesn't match a supported "
Traceback (most recent call last):
  File "main.py", line 127, in <module>
    with telegram_client as tc:
  File "/usr/local/lib/python3.8/dist-packages/telethon/helpers.py", line 219, in _sync_enter
    return loop.run_until_complete(self.__aenter__())
  File "/usr/lib/python3.8/asyncio/base_events.py", line 616, in run_until_complete
    return future.result()
  File "/usr/local/lib/python3.8/dist-packages/telethon/client/auth.py", line 735, in __aenter__
    return await self.start()
  File "/usr/local/lib/python3.8/dist-packages/telethon/client/auth.py", line 171, in _start
    value = phone()
  File "/usr/local/lib/python3.8/dist-packages/telethon/client/auth.py", line 22, in <lambda>
    phone: typing.Callable[[], str] = lambda: input('Please enter your phone (or bot token): '),
OSError: [Errno 9] Bad file descriptor
